<mujoco model="unnamed_model">
  <option timestep="0.01"/>
  <visual>
    <headlight ambient="0.5 0.5 0.5"/>
  </visual>
  <default>
    <default class="/"/>
  </default>
  <worldbody>
    <light name="//unnamed_light_0" class="/" pos="0 0 3" dir="0 0 -1" diffuse="0.5 0.5 0.5"/>
    <geom name="//unnamed_geom_0" class="/" type="plane" size="50 50 0.10000000000000001"/>
    <body name="//unnamed_body_0" pos="0 0 4">
      <joint name="//unnamed_joint_0" class="/" type="free"/>
      <geom name="//unnamed_geom_1" class="/" type="ellipsoid" size="0.10000000000000001 0.10000000000000001 0.050000000000000003" rgba="0.91000000000000003 0.27800000000000002 0.070999999999999994 1" pos="0 0 0"/>
      <geom name="//unnamed_geom_2" class="/" type="ellipsoid" size="0.14999999999999999 0.14999999999999999 0.10000000000000001" rgba="0.247 0.035000000000000003 0.97999999999999998 1" pos="0.20000000000000001 0 0"/>
      <body name="limb1" pos="0.050000000000000003 0.14999999999999999 -0.28776949967436416">
        <geom name="//unnamed_geom_3" class="/" type="cylinder" size="0.011519885648044941 0.28776949967436416" rgba="0 1 0 1"/>
        <joint name="limb1_joint" class="/" type="hinge" pos="0 0 0.28776949967436416" axis="0 1 0" range="-45 45"/>
      </body>
      <body name="limb2" pos="0.050000000000000003 -0.14999999999999999 -0.17011961616703841">
        <geom name="//unnamed_geom_4" class="/" type="cylinder" size="0.019646572941031962 0.17011961616703841" rgba="0 1 0 1"/>
        <joint name="limb2_joint" class="/" type="hinge" pos="0 0 0.17011961616703841" axis="0 1 0" range="-45 45"/>
      </body>
      <body name="limb3" pos="0.29999999999999999 0.20000000000000001 -0.39483240670167252">
        <geom name="//unnamed_geom_5" class="/" type="cylinder" size="0.01207307090812167 0.39483240670167252" rgba="0 1 0 1"/>
        <joint name="limb3_joint" class="/" type="hinge" pos="0 0 0.39483240670167252" axis="0 1 0" range="-45 45"/>
      </body>
      <body name="back_limb1" pos="0.050000000000000003 -0.14999999999999999 0.21465220423279086">
        <geom name="//unnamed_geom_6" class="/" type="cylinder" size="0.016785271627413133 0.21465220423279086" rgba="0 1 0 1"/>
        <joint name="back_limb1_joint" class="/" type="hinge" pos="0 0 -0.21465220423279086" axis="0 1 0" range="-45 45"/>
      </body>
      <body name="back_limb2" pos="0.29999999999999999 0.20000000000000001 0.18882671810588667">
        <geom name="//unnamed_geom_7" class="/" type="cylinder" size="0.025919505710851123 0.18882671810588667" rgba="0 1 0 1"/>
        <joint name="back_limb2_joint" class="/" type="hinge" pos="0 0 -0.18882671810588667" axis="0 1 0" range="-45 45"/>
      </body>
    </body>
  </worldbody>
  <actuator>
    <motor name="motor_limb1_joint" class="/" ctrllimited="true" ctrlrange="-45 45" gear="1" joint="limb1_joint"/>
    <motor name="motor_limb2_joint" class="/" ctrllimited="true" ctrlrange="-45 45" gear="1" joint="limb2_joint"/>
    <motor name="motor_limb3_joint" class="/" ctrllimited="true" ctrlrange="-45 45" gear="1" joint="limb3_joint"/>
    <motor name="motor_back_back_limb1_joint" class="/" ctrllimited="true" ctrlrange="-45 45" gear="1" joint="back_limb1_joint"/>
    <motor name="motor_back_back_limb2_joint" class="/" ctrllimited="true" ctrlrange="-45 45" gear="1" joint="back_limb2_joint"/>
  </actuator>
</mujoco>
