<mujoco model="unnamed_model">
  <option timestep="0.01"/>
  <visual>
    <headlight ambient="0.5 0.5 0.5"/>
  </visual>
  <default>
    <default class="/"/>
  </default>
  <worldbody>
    <light name="//unnamed_light_0" class="/" pos="0 0 3" dir="0 0 -1" diffuse="0.5 0.5 0.5"/>
    <geom name="//unnamed_geom_0" class="/" type="plane" size="50 50 0.10000000000000001"/>
    <body name="//unnamed_body_0" pos="0 0 4">
      <joint name="//unnamed_joint_0" class="/" type="free"/>
      <geom name="//unnamed_geom_1" class="/" type="ellipsoid" size="0.10000000000000001 0.10000000000000001 0.050000000000000003" rgba="0.91000000000000003 0.27800000000000002 0.070999999999999994 1" pos="0 0 0"/>
      <geom name="//unnamed_geom_2" class="/" type="ellipsoid" size="0.14999999999999999 0.14999999999999999 0.10000000000000001" rgba="0.247 0.035000000000000003 0.97999999999999998 1" pos="0.20000000000000001 0 0"/>
      <body name="limb1" pos="0.050000000000000003 0.14999999999999999 -0.33539649480506761">
        <geom name="//unnamed_geom_3" class="/" type="cylinder" size="0.022894597576307456 0.33539649480506761" rgba="0 1 0 1"/>
        <joint name="limb1_joint" class="/" type="hinge" pos="0 0 0.33539649480506761" axis="0 1 0" range="-45 45"/>
      </body>
      <body name="limb2" pos="0.29999999999999999 0.20000000000000001 -0.43775472249366321">
        <geom name="//unnamed_geom_4" class="/" type="cylinder" size="0.020002621732405461 0.43775472249366321" rgba="0 1 0 1"/>
        <joint name="limb2_joint" class="/" type="hinge" pos="0 0 0.43775472249366321" axis="0 1 0" range="-45 45"/>
      </body>
      <body name="back_limb1" pos="0.050000000000000003 0.14999999999999999 0.47624148012694079">
        <geom name="//unnamed_geom_5" class="/" type="cylinder" size="0.022125823174684263 0.47624148012694079" rgba="0 1 0 1"/>
        <joint name="back_limb1_joint" class="/" type="hinge" pos="0 0 -0.47624148012694079" axis="0 1 0" range="-45 45"/>
      </body>
      <body name="back_limb2" pos="0.050000000000000003 -0.14999999999999999 0.38885743750740853">
        <geom name="//unnamed_geom_6" class="/" type="cylinder" size="0.012206075583563212 0.38885743750740853" rgba="0 1 0 1"/>
        <joint name="back_limb2_joint" class="/" type="hinge" pos="0 0 -0.38885743750740853" axis="0 1 0" range="-45 45"/>
      </body>
      <body name="back_limb3" pos="0.29999999999999999 0.20000000000000001 0.11278337660175382">
        <geom name="//unnamed_geom_7" class="/" type="cylinder" size="0.026179973196683595 0.11278337660175382" rgba="0 1 0 1"/>
        <joint name="back_limb3_joint" class="/" type="hinge" pos="0 0 -0.11278337660175382" axis="0 1 0" range="-45 45"/>
      </body>
    </body>
  </worldbody>
  <actuator>
    <motor name="motor_limb1_joint" class="/" ctrllimited="true" ctrlrange="-45 45" gear="1" joint="limb1_joint"/>
    <motor name="motor_limb2_joint" class="/" ctrllimited="true" ctrlrange="-45 45" gear="1" joint="limb2_joint"/>
    <motor name="motor_back_back_limb1_joint" class="/" ctrllimited="true" ctrlrange="-45 45" gear="1" joint="back_limb1_joint"/>
    <motor name="motor_back_back_limb2_joint" class="/" ctrllimited="true" ctrlrange="-45 45" gear="1" joint="back_limb2_joint"/>
    <motor name="motor_back_back_limb3_joint" class="/" ctrllimited="true" ctrlrange="-45 45" gear="1" joint="back_limb3_joint"/>
  </actuator>
</mujoco>
