<mujoco model="unnamed_model">
  <option timestep="0.01"/>
  <visual>
    <headlight ambient="0.5 0.5 0.5"/>
  </visual>
  <default>
    <default class="/"/>
  </default>
  <worldbody>
    <light name="//unnamed_light_0" class="/" pos="0 0 3" dir="0 0 -1" diffuse="0.5 0.5 0.5"/>
    <geom name="//unnamed_geom_0" class="/" type="plane" size="50 50 0.10000000000000001"/>
    <body name="//unnamed_body_0" pos="0 0 4">
      <joint name="//unnamed_joint_0" class="/" type="free"/>
      <geom name="//unnamed_geom_1" class="/" type="ellipsoid" size="0.10000000000000001 0.10000000000000001 0.050000000000000003" rgba="0.91000000000000003 0.27800000000000002 0.070999999999999994 1" pos="0 0 0"/>
      <geom name="//unnamed_geom_2" class="/" type="ellipsoid" size="0.14999999999999999 0.14999999999999999 0.10000000000000001" rgba="0.247 0.035000000000000003 0.97999999999999998 1" pos="0.20000000000000001 0 0"/>
      <body name="limb1" pos="0.050000000000000003 0.14999999999999999 -0.34519035883524474">
        <geom name="//unnamed_geom_3" class="/" type="cylinder" size="0.037099952429361351 0.34519035883524474" rgba="0 1 0 1"/>
        <joint name="limb1_joint" class="/" type="hinge" pos="0 0 0.34519035883524474" axis="0 1 0" range="-45 45"/>
      </body>
      <body name="limb2" pos="0.050000000000000003 -0.14999999999999999 -0.353452324198816">
        <geom name="//unnamed_geom_4" class="/" type="cylinder" size="0.020418754804973183 0.353452324198816" rgba="0 1 0 1"/>
        <joint name="limb2_joint" class="/" type="hinge" pos="0 0 0.353452324198816" axis="0 1 0" range="-45 45"/>
      </body>
      <body name="limb3" pos="0.29999999999999999 0.20000000000000001 -0.27850455667683416">
        <geom name="//unnamed_geom_5" class="/" type="cylinder" size="0.035798794203300975 0.27850455667683416" rgba="0 1 0 1"/>
        <joint name="limb3_joint" class="/" type="hinge" pos="0 0 0.27850455667683416" axis="0 1 0" range="-45 45"/>
      </body>
      <body name="back_limb1" pos="0.050000000000000003 0.14999999999999999 0.12594147777112449">
        <geom name="//unnamed_geom_6" class="/" type="cylinder" size="0.027853309598328074 0.12594147777112449" rgba="0 1 0 1"/>
        <joint name="back_limb1_joint" class="/" type="hinge" pos="0 0 -0.12594147777112449" axis="0 1 0" range="-45 45"/>
      </body>
      <body name="back_limb2" pos="0.29999999999999999 0.20000000000000001 0.25094189580682114">
        <geom name="//unnamed_geom_7" class="/" type="cylinder" size="0.014260501205424114 0.25094189580682114" rgba="0 1 0 1"/>
        <joint name="back_limb2_joint" class="/" type="hinge" pos="0 0 -0.25094189580682114" axis="0 1 0" range="-45 45"/>
      </body>
    </body>
  </worldbody>
  <actuator>
    <motor name="motor_limb1_joint" class="/" ctrllimited="true" ctrlrange="-45 45" gear="1" joint="limb1_joint"/>
    <motor name="motor_limb2_joint" class="/" ctrllimited="true" ctrlrange="-45 45" gear="1" joint="limb2_joint"/>
    <motor name="motor_limb3_joint" class="/" ctrllimited="true" ctrlrange="-45 45" gear="1" joint="limb3_joint"/>
    <motor name="motor_back_back_limb1_joint" class="/" ctrllimited="true" ctrlrange="-45 45" gear="1" joint="back_limb1_joint"/>
    <motor name="motor_back_back_limb2_joint" class="/" ctrllimited="true" ctrlrange="-45 45" gear="1" joint="back_limb2_joint"/>
  </actuator>
</mujoco>
