<mujoco>
    <worldbody>
        <light diffuse=".5 .5 .5" pos="0 0 10" dir="0 0 -1"/>
        <geom type="plane" size="50 50 0.1" rgba="1 1 1 1"/>
        <!-- Main body -->
        <body name="main_body" pos="0 0 4">
            <!-- <joint type="free"/> -->
            <!-- Cephalothorax -->
            <geom type="ellipsoid" size="0.1 0.1 0.05" pos="0 0 0" />

            <!-- Abdomen -->
            <geom type="ellipsoid" size="0.15 0.15 0.1" pos="0.2 0 0" />
            
            <!-- Define legs with a more realistic alignment -->
            <!-- Leg 1 -->
            <body name="leg1" pos="0.05 0.15 -0.1">
                <joint type="hinge" pos="0 0 0.1" axis="1 0 0" name="leg1_joint1" />
                <!-- radiu and half height -->
                <geom type="cylinder" size="0.02 0.1" />
                <body name="leg1_2" pos="0 0 -0.2">
                    <joint type="hinge" pos="0 0 0.1" axis="0 1 0" name="leg1_joint2" />
                    <geom type="cylinder" size="0.02 0.1" />
                    <!-- <body name="leg1_3" pos="0 0.2 0">
                        <joint type="hinge" axis="1 0 0" name="leg1_joint3" />
                        <geom type="cylinder" size="0.01 0.1" />
                    </body> -->
                </body>
            </body>
            <!-- Additional legs should be defined similarly, adjusting their position and orientation accordingly. -->
            <body name="leg2" pos="0.05 -0.15 -0.1">
                <joint type="hinge" pos="0 0 0.1" axis="1 0 0" name="leg2_joint1" />
                <!-- radiu and half height -->
                <geom type="cylinder" size="0.02 0.1" />
                <body name="leg2_2" pos="0 0 -0.2">
                    <joint type="hinge" pos="0 0 0.1" axis="0 1 0" name="leg2_joint2" />
                    <geom type="cylinder" size="0.02 0.1" />
                </body>
            </body>

            <body name="leg3" pos="0.3 0.2 -0.1">
                <joint type="hinge" pos="0 0 0.1" axis="1 0 0" name="leg3_joint1" />
                <!-- radiu and half height -->
                <geom type="cylinder" size="0.02 0.1" />
                <body name="leg3_2" pos="0 0 -0.2">
                    <joint type="hinge" pos="0 0 0.1" axis="0 1 0" name="leg3_joint2" />
                    <geom type="cylinder" size="0.02 0.1" />
                </body>
            </body>

            <body name="leg4" pos="0.3 -0.2 -0.1">
                <joint type="hinge" pos="0 0 0.1" axis="1 0 0" name="leg4_joint1" />
                <!-- radiu and half height -->
                <geom type="cylinder" size="0.02 0.1" />
                <body name="leg4_2" pos="0 0 -0.2">
                    <joint type="hinge" pos="0 0 0.1" axis="0 1 0" name="leg4_joint2" />
                    <geom type="cylinder" size="0.02 0.1" />
                </body>
            </body>
        </body>
    </worldbody>
    <actuator>
        <!-- Actuators for leg joints -->
        <motor joint="leg1_joint1" ctrlrange="-1 1" />
        <motor joint="leg1_joint2" ctrlrange="-1 1" />
        <!-- <motor joint="leg1_joint3" ctrlrange="-1 1" /> -->
        <!-- Additional actuators for other legs -->
    </actuator>
</mujoco>
