<mujoco model="unnamed_model">
  <option timestep="0.01"/>
  <visual>
    <headlight ambient="0.5 0.5 0.5"/>
  </visual>
  <default>
    <default class="/"/>
  </default>
  <worldbody>
    <light name="//unnamed_light_0" class="/" pos="0 0 3" dir="0 0 -1" diffuse="0.5 0.5 0.5"/>
    <geom name="//unnamed_geom_0" class="/" type="plane" size="50 50 0.10000000000000001"/>
    <body name="//unnamed_body_0" pos="0 0 4">
      <joint name="//unnamed_joint_0" class="/" type="free"/>
      <geom name="//unnamed_geom_1" class="/" type="ellipsoid" size="0.10000000000000001 0.10000000000000001 0.050000000000000003" pos="0 0 0"/>
      <geom name="//unnamed_geom_2" class="/" type="ellipsoid" size="0.14999999999999999 0.14999999999999999 0.10000000000000001" pos="0.20000000000000001 0 0"/>
      <body name="limb1" pos="0.050000000000000003 0.14999999999999999 -0.10000000000000001">
        <geom name="//unnamed_geom_3" class="/" type="cylinder" size="0.02 0.10000000000000001" rgba="0 1 0 1"/>
        <joint name="limb1_joint" class="/" type="hinge" pos="0 0 0.10000000000000001" axis="0 1 0" range="-45 45"/>
      </body>
      <body name="limb2" pos="0.050000000000000003 -0.14999999999999999 -0.10000000000000001">
        <geom name="//unnamed_geom_4" class="/" type="cylinder" size="0.02 0.10000000000000001" rgba="0 1 0 1"/>
        <joint name="limb2_joint" class="/" type="hinge" pos="0 0 0.10000000000000001" axis="0 1 0" range="-45 45"/>
      </body>
      <body name="limb3" pos="0.29999999999999999 0.20000000000000001 -0.10000000000000001">
        <geom name="//unnamed_geom_5" class="/" type="cylinder" size="0.02 0.10000000000000001" rgba="0 1 0 1"/>
        <joint name="limb3_joint" class="/" type="hinge" pos="0 0 0.10000000000000001" axis="0 1 0" range="-45 45"/>
      </body>
      <body name="limb4" pos="0.29999999999999999 -0.20000000000000001 -0.10000000000000001">
        <geom name="//unnamed_geom_6" class="/" type="cylinder" size="0.02 0.10000000000000001" rgba="0 1 0 1"/>
        <joint name="limb4_joint" class="/" type="hinge" pos="0 0 0.10000000000000001" axis="0 1 0" range="-45 45"/>
      </body>
    </body>
  </worldbody>
  <actuator>
    <motor name="motor_limb1_joint" class="/" ctrllimited="true" ctrlrange="-45 45" gear="1" joint="limb1_joint"/>
    <motor name="motor_limb2_joint" class="/" ctrllimited="true" ctrlrange="-45 45" gear="1" joint="limb2_joint"/>
    <motor name="motor_limb3_joint" class="/" ctrllimited="true" ctrlrange="-45 45" gear="1" joint="limb3_joint"/>
    <motor name="motor_limb4_joint" class="/" ctrllimited="true" ctrlrange="-45 45" gear="1" joint="limb4_joint"/>
  </actuator>
</mujoco>
