<mujoco model="unnamed_model">
  <option timestep="0.01"/>
  <visual>
    <headlight ambient="0.5 0.5 0.5"/>
  </visual>
  <default>
    <default class="/"/>
  </default>
  <worldbody>
    <light name="//unnamed_light_0" class="/" pos="0 0 3" dir="0 0 -1" diffuse="0.5 0.5 0.5"/>
    <geom name="//unnamed_geom_0" class="/" type="plane" size="50 50 0.10000000000000001"/>
    <body name="//unnamed_body_0" pos="0 0 4">
      <joint name="//unnamed_joint_0" class="/" type="free"/>
      <geom name="//unnamed_geom_1" class="/" type="ellipsoid" size="0.38548075575387841 0.26798713171656741 0.1452004561483676" rgba="0.247 0.035000000000000003 0.97999999999999998 1" pos="0 0 0"/>
      <body name="limb0" pos="-0.07214536872898869 0.26798713171656741 0.15427922134028071">
        <geom name="//unnamed_geom_2" class="/" type="cylinder" size="0.025992100353521487 0.15427922134028071" rgba="0 1 0 1"/>
        <joint name="0_joint" class="/" type="hinge" pos="0 0 -0.15427922134028071" axis="0 1 0" range="-45 45"/>
      </body>
      <body name="limb1" pos="0.22825054707942577 -0.26798713171656741 0.28723943196440571">
        <geom name="//unnamed_geom_3" class="/" type="cylinder" size="0.039135236712299862 0.28723943196440571" rgba="0 1 0 1"/>
        <joint name="1_joint" class="/" type="hinge" pos="0 0 -0.28723943196440571" axis="0 1 0" range="-45 45"/>
      </body>
      <body name="limb2" pos="0.18172725869811557 -0.26798713171656741 -0.44909702097792314">
        <geom name="//unnamed_geom_4" class="/" type="cylinder" size="0.036787874496359084 0.44909702097792314" rgba="0 1 0 1"/>
        <joint name="2_joint" class="/" type="hinge" pos="0 0 0.44909702097792314" axis="0 1 0" range="-45 45"/>
      </body>
    </body>
  </worldbody>
  <actuator>
    <motor name="motor_0_joint" class="/" ctrllimited="true" ctrlrange="-45 45" gear="10" joint="0_joint"/>
    <motor name="motor_1_joint" class="/" ctrllimited="true" ctrlrange="-45 45" gear="10" joint="1_joint"/>
    <motor name="motor_2_joint" class="/" ctrllimited="true" ctrlrange="-45 45" gear="10" joint="2_joint"/>
  </actuator>
</mujoco>
