<mujoco model="unnamed_model">
  <option timestep="0.01"/>
  <visual>
    <headlight ambient="0.5 0.5 0.5"/>
  </visual>
  <default>
    <default class="/"/>
  </default>
  <worldbody>
    <light name="//unnamed_light_0" class="/" pos="0 0 3" dir="0 0 -1" diffuse="0.5 0.5 0.5"/>
    <geom name="//unnamed_geom_0" class="/" type="plane" size="50 50 0.10000000000000001"/>
    <body name="//unnamed_body_0" pos="0 0 4">
      <joint name="//unnamed_joint_0" class="/" type="free"/>
      <geom name="//unnamed_geom_1" class="/" type="ellipsoid" size="0.20517978357399941 0.32827401439382653 0.17708353027529414" rgba="0.247 0.035000000000000003 0.97999999999999998 1" pos="0 0 0"/>
      <geom name="//unnamed_geom_2" class="/" type="ellipsoid" size="0.058373150481432698 0.083182700167458393 0.079021272647662316" rgba="0.91000000000000003 0.27800000000000002 0.070999999999999994 1" pos="0.26355293405543212 0 0"/>
      <body name="limb0" pos="0.16753924216469795 0.32827401439382653 0.25209861335193351">
        <geom name="//unnamed_geom_3" class="/" type="cylinder" size="0.034738534367654145 0.25209861335193351" rgba="0 1 0 1"/>
        <joint name="0_joint" class="/" type="hinge" pos="0 0 -0.25209861335193351" axis="0 1 0" range="-45 45"/>
      </body>
      <body name="limb1" pos="0.10755585358272518 0.32827401439382653 0.43105409183604437">
        <geom name="//unnamed_geom_4" class="/" type="cylinder" size="0.025268863888981752 0.43105409183604437" rgba="0 1 0 1"/>
        <joint name="1_joint" class="/" type="hinge" pos="0 0 -0.43105409183604437" axis="0 1 0" range="-45 45"/>
      </body>
    </body>
  </worldbody>
  <actuator>
    <motor name="motor_0_joint" class="/" ctrllimited="true" ctrlrange="-45 45" gear="10" joint="0_joint"/>
    <motor name="motor_1_joint" class="/" ctrllimited="true" ctrlrange="-45 45" gear="10" joint="1_joint"/>
  </actuator>
</mujoco>
